
2015-02-08 11:36:24 - Error:
Traceback (most recent call last):
  File "bot.py", line 586, in main
    bot.runbot()
  File "bot.py", line 565, in runbot
    self.event(subreddit)
  File "bot.py", line 516, in event
    for thread in new_thread:
  File "/usr/local/lib/python3.4/site-packages/praw/__init__.py", line 504, in get_content
    page_data = self.request_json(url, params=params)
  File "/usr/local/lib/python3.4/site-packages/praw/decorators.py", line 163, in wrapped
    return_value = function(reddit_session, *args, **kwargs)
  File "/usr/local/lib/python3.4/site-packages/praw/__init__.py", line 557, in request_json
    retry_on_error=retry_on_error)
  File "/usr/local/lib/python3.4/site-packages/praw/__init__.py", line 399, in _request
    _raise_response_exceptions(response)
  File "/usr/local/lib/python3.4/site-packages/praw/internal.py", line 178, in _raise_response_exceptions
    response.raise_for_status()
  File "/usr/local/lib/python3.4/site-packages/requests/models.py", line 831, in raise_for_status
    raise HTTPError(http_error_msg, response=self)
requests.exceptions.HTTPError: 503 Server Error: Service Unavailable



2015-02-09 07:28:44 - Error:
Traceback (most recent call last):
  File "bot.py", line 586, in main
    bot.runbot()
  File "bot.py", line 564, in runbot
    self.comment_search(subreddit)
  File "bot.py", line 148, in comment_search
    for comment in comment_list:
  File "/usr/local/lib/python3.4/site-packages/praw/__init__.py", line 504, in get_content
    page_data = self.request_json(url, params=params)
  File "/usr/local/lib/python3.4/site-packages/praw/decorators.py", line 163, in wrapped
    return_value = function(reddit_session, *args, **kwargs)
  File "/usr/local/lib/python3.4/site-packages/praw/__init__.py", line 557, in request_json
    retry_on_error=retry_on_error)
  File "/usr/local/lib/python3.4/site-packages/praw/__init__.py", line 399, in _request
    _raise_response_exceptions(response)
  File "/usr/local/lib/python3.4/site-packages/praw/internal.py", line 178, in _raise_response_exceptions
    response.raise_for_status()
  File "/usr/local/lib/python3.4/site-packages/requests/models.py", line 831, in raise_for_status
    raise HTTPError(http_error_msg, response=self)
requests.exceptions.HTTPError: 522 Server Error: Origin Connection Time-out



2015-02-09 07:30:46 - Error:
Traceback (most recent call last):
  File "bot.py", line 586, in main
    bot.runbot()
  File "bot.py", line 564, in runbot
    self.comment_search(subreddit)
  File "bot.py", line 148, in comment_search
    for comment in comment_list:
  File "/usr/local/lib/python3.4/site-packages/praw/__init__.py", line 504, in get_content
    page_data = self.request_json(url, params=params)
  File "/usr/local/lib/python3.4/site-packages/praw/decorators.py", line 163, in wrapped
    return_value = function(reddit_session, *args, **kwargs)
  File "/usr/local/lib/python3.4/site-packages/praw/__init__.py", line 557, in request_json
    retry_on_error=retry_on_error)
  File "/usr/local/lib/python3.4/site-packages/praw/__init__.py", line 399, in _request
    _raise_response_exceptions(response)
  File "/usr/local/lib/python3.4/site-packages/praw/internal.py", line 178, in _raise_response_exceptions
    response.raise_for_status()
  File "/usr/local/lib/python3.4/site-packages/requests/models.py", line 831, in raise_for_status
    raise HTTPError(http_error_msg, response=self)
requests.exceptions.HTTPError: 522 Server Error: Origin Connection Time-out



2015-02-09 07:32:04 - Error:
Traceback (most recent call last):
  File "bot.py", line 586, in main
    bot.runbot()
  File "bot.py", line 564, in runbot
    self.comment_search(subreddit)
  File "bot.py", line 148, in comment_search
    for comment in comment_list:
  File "/usr/local/lib/python3.4/site-packages/praw/__init__.py", line 504, in get_content
    page_data = self.request_json(url, params=params)
  File "/usr/local/lib/python3.4/site-packages/praw/decorators.py", line 163, in wrapped
    return_value = function(reddit_session, *args, **kwargs)
  File "/usr/local/lib/python3.4/site-packages/praw/__init__.py", line 557, in request_json
    retry_on_error=retry_on_error)
  File "/usr/local/lib/python3.4/site-packages/praw/__init__.py", line 399, in _request
    _raise_response_exceptions(response)
  File "/usr/local/lib/python3.4/site-packages/praw/internal.py", line 178, in _raise_response_exceptions
    response.raise_for_status()
  File "/usr/local/lib/python3.4/site-packages/requests/models.py", line 831, in raise_for_status
    raise HTTPError(http_error_msg, response=self)
requests.exceptions.HTTPError: 522 Server Error: Origin Connection Time-out



2015-02-09 11:20:10 - Error:
Traceback (most recent call last):
  File "bot.py", line 589, in main
    bot.runbot()
  File "bot.py", line 573, in runbot
    time.sleep(30)
KeyboardInterrupt



2015-02-09 11:21:16 - Error:
Traceback (most recent call last):
  File "bot.py", line 593, in main
    bot.runbot()
  File "bot.py", line 566, in runbot
    self.comment_search(subreddit)
  File "bot.py", line 150, in comment_search
    for comment in comment_list:
  File "/usr/local/lib/python3.4/site-packages/praw/__init__.py", line 504, in get_content
    page_data = self.request_json(url, params=params)
  File "/usr/local/lib/python3.4/site-packages/praw/decorators.py", line 163, in wrapped
    return_value = function(reddit_session, *args, **kwargs)
  File "/usr/local/lib/python3.4/site-packages/praw/__init__.py", line 557, in request_json
    retry_on_error=retry_on_error)
  File "/usr/local/lib/python3.4/site-packages/praw/__init__.py", line 398, in _request
    response = handle_redirect()
  File "/usr/local/lib/python3.4/site-packages/praw/__init__.py", line 371, in handle_redirect
    timeout=timeout, **kwargs)
  File "/usr/local/lib/python3.4/site-packages/praw/handlers.py", line 145, in wrapped
    result = function(cls, **kwargs)
  File "/usr/local/lib/python3.4/site-packages/praw/handlers.py", line 53, in wrapped
    time.sleep(delay)
KeyboardInterrupt



2015-02-13 19:20:05 - Error:
Traceback (most recent call last):
  File "bot.py", line 589, in main
    bot.runbot()
  File "bot.py", line 564, in runbot
    self.event(subreddit)
  File "bot.py", line 514, in event
    print ('Datetime not set. Searching for datetime in subreddit {0}'.format(subreddit))
OSError: [Errno 5] Input/output error



2015-02-14 19:20:59 - Error:
Traceback (most recent call last):
  File "bot.py", line 589, in main
    bot.runbot()
  File "bot.py", line 566, in runbot
    self.message_search()
  File "bot.py", line 135, in message_search
    self.commands[command](user, msg_text, msg)
  File "bot.py", line 349, in register
    if type(check_registry(registry_cache[friend][2])) == str:
NameError: name 'check_registry' is not defined



2015-02-14 19:22:40 - Error:
Traceback (most recent call last):
  File "bot.py", line 589, in main
    bot.runbot()
  File "bot.py", line 566, in runbot
    self.message_search()
  File "bot.py", line 135, in message_search
    self.commands[command](user, msg_text, msg)
  File "bot.py", line 349, in register
    if type(check_registry(registry_cache[friend][2])) == str:
NameError: name 'check_registry' is not defined



2015-02-14 19:23:50 - Error:
Traceback (most recent call last):
  File "bot.py", line 589, in main
    bot.runbot()
  File "bot.py", line 566, in runbot
    self.message_search()
  File "bot.py", line 135, in message_search
    self.commands[command](user, msg_text, msg)
  File "bot.py", line 349, in register
    if type(check_registry(registry_cache[friend][2])) == str:
NameError: name 'check_registry' is not defined



2015-02-14 19:30:19 - Error:
Traceback (most recent call last):
  File "bot.py", line 589, in main
    bot.runbot()
  File "bot.py", line 573, in runbot
    time.sleep(30)
KeyboardInterrupt



2015-02-15 06:41:34 - Error:
Traceback (most recent call last):
  File "bot.py", line 589, in main
    try:
  File "bot.py", line 573, in runbot
    print ('Iteration complete')
KeyboardInterrupt



2015-02-15 06:45:14 - Error:
Traceback (most recent call last):
  File "bot.py", line 590, in main
    try:
  File "bot.py", line 574, in runbot
    print ('Iteration complete')
KeyboardInterrupt



