
2015-02-08 11:36:24 - Error:
Traceback (most recent call last):
  File "bot.py", line 586, in main
    bot.runbot()
  File "bot.py", line 565, in runbot
    self.event(subreddit)
  File "bot.py", line 516, in event
    for thread in new_thread:
  File "/usr/local/lib/python3.4/site-packages/praw/__init__.py", line 504, in get_content
    page_data = self.request_json(url, params=params)
  File "/usr/local/lib/python3.4/site-packages/praw/decorators.py", line 163, in wrapped
    return_value = function(reddit_session, *args, **kwargs)
  File "/usr/local/lib/python3.4/site-packages/praw/__init__.py", line 557, in request_json
    retry_on_error=retry_on_error)
  File "/usr/local/lib/python3.4/site-packages/praw/__init__.py", line 399, in _request
    _raise_response_exceptions(response)
  File "/usr/local/lib/python3.4/site-packages/praw/internal.py", line 178, in _raise_response_exceptions
    response.raise_for_status()
  File "/usr/local/lib/python3.4/site-packages/requests/models.py", line 831, in raise_for_status
    raise HTTPError(http_error_msg, response=self)
requests.exceptions.HTTPError: 503 Server Error: Service Unavailable



